Workbook

Sheet raw_podaci
A1: run_id | B1: total_efficiency | C1: sheet_1_eff | D1: sheet_2_eff | E1: sheet_3_eff | F1: last_sheet_true_eff | G1: execution_time_ms | H1: total_waste_mm2 | I1: sheets_used | J1: Column3 | K1: Efficiency per ms | L1: Column2 | M1: Waste per sheet | N1: Column1 | O1: Efficiency drop on last sheet
A2: 1 | B2: 95.24 | C2: 97.77 | D2: 96.75 | E2: 94.17 | F2: 85.98 | G2: 91740 | H2: 934804 | I2: 4 | K2: =Table1[[#This Row],[total_efficiency]]/Table1[[#This Row],[execution_time_ms]] -> 0.0010381513 | M2: =Table1[[#This Row],[total_waste_mm2]]/4 -> 233701 | O2: =Table1[[#This Row],[sheet_3_eff]]-Table1[[#This Row],[last_sheet_true_eff]] -> 8.19
A3: 2 | B3: 95.13 | C3: 97.77 | D3: 96.57 | E3: 92.36 | F3: 91.15 | G3: 187938 | H3: 934804 | I3: 4 | K3: =Table1[[#This Row],[total_efficiency]]/Table1[[#This Row],[execution_time_ms]] -> 0.00050617757 | M3: =Table1[[#This Row],[total_waste_mm2]]/4 -> 233701 | O3: =Table1[[#This Row],[sheet_3_eff]]-Table1[[#This Row],[last_sheet_true_eff]] -> 1.21
A4: 3 | B4: 95.45 | C4: 97.77 | D4: 96.08 | E4: 94.96 | F4: 87.61 | G4: 188765 | H4: 985024 | I4: 4 | K4: =Table1[[#This Row],[total_efficiency]]/Table1[[#This Row],[execution_time_ms]] -> 0.00050565518 | M4: =Table1[[#This Row],[total_waste_mm2]]/4 -> 246256 | O4: =Table1[[#This Row],[sheet_3_eff]]-Table1[[#This Row],[last_sheet_true_eff]] -> 7.35
A5: 4 | B5: 94.17 | C5: 97.77 | D5: 95.98 | E5: 95.8 | F5: 74.54 | G5: 85793 | H5: 1155214 | I5: 4 | K5: =Table1[[#This Row],[total_efficiency]]/Table1[[#This Row],[execution_time_ms]] -> 0.001097642 | M5: =Table1[[#This Row],[total_waste_mm2]]/4 -> 288803.5 | O5: =Table1[[#This Row],[sheet_3_eff]]-Table1[[#This Row],[last_sheet_true_eff]] -> 21.26
A6: 5 | B6: 95.12 | C6: 97.77 | D6: 96.42 | E6: 94.02 | F6: 86.38 | G6: 92514 | H6: 934804 | I6: 4 | K6: =Table1[[#This Row],[total_efficiency]]/Table1[[#This Row],[execution_time_ms]] -> 0.0010281687 | M6: =Table1[[#This Row],[total_waste_mm2]]/4 -> 233701 | O6: =Table1[[#This Row],[sheet_3_eff]]-Table1[[#This Row],[last_sheet_true_eff]] -> 7.64
A7: 6 | B7: 94.4 | C7: 97.77 | D7: 96.35 | E7: 95.1 | F7: 77.3 | G7: 91662 | H7: 1104994 | I7: 4 | K7: =Table1[[#This Row],[total_efficiency]]/Table1[[#This Row],[execution_time_ms]] -> 0.0010298706 | M7: =Table1[[#This Row],[total_waste_mm2]]/4 -> 276248.5 | O7: =Table1[[#This Row],[sheet_3_eff]]-Table1[[#This Row],[last_sheet_true_eff]] -> 17.8
A8: 7 | B8: 93.86 | C8: 97.77 | D8: 95.78 | E8: 94.38 | F8: 76.7 | G8: 86366 | H8: 1205434 | I8: 4 | K8: =Table1[[#This Row],[total_efficiency]]/Table1[[#This Row],[execution_time_ms]] -> 0.0010867703 | M8: =Table1[[#This Row],[total_waste_mm2]]/4 -> 301358.5 | O8: =Table1[[#This Row],[sheet_3_eff]]-Table1[[#This Row],[last_sheet_true_eff]] -> 17.68
A9: 8 | B9: 95.9 | C9: 97.77 | D9: 96.75 | E9: 95.36 | F9: 88.65 | G9: 86375 | H9: 884584 | I9: 4 | K9: =Table1[[#This Row],[total_efficiency]]/Table1[[#This Row],[execution_time_ms]] -> 0.001110275 | M9: =Table1[[#This Row],[total_waste_mm2]]/4 -> 221146 | O9: =Table1[[#This Row],[sheet_3_eff]]-Table1[[#This Row],[last_sheet_true_eff]] -> 6.71
A10: 9 | B10: 95.9 | C10: 97.77 | D10: 96.75 | E10: 95.36 | F10: 88.65 | G10: 86806 | H10: 884584 | I10: 4 | K10: =Table1[[#This Row],[total_efficiency]]/Table1[[#This Row],[execution_time_ms]] -> 0.0011047623 | M10: =Table1[[#This Row],[total_waste_mm2]]/4 -> 221146 | O10: =Table1[[#This Row],[sheet_3_eff]]-Table1[[#This Row],[last_sheet_true_eff]] -> 6.71
A11: 10 | B11: 96.32 | C11: 97.77 | D11: 96.67 | E11: 95.14 | F11: 94.16 | G11: 86498 | H11: 733924 | I11: 4 | K11: =Table1[[#This Row],[total_efficiency]]/Table1[[#This Row],[execution_time_ms]] -> 0.0011135518 | M11: =Table1[[#This Row],[total_waste_mm2]]/4 -> 183481 | O11: =Table1[[#This Row],[sheet_3_eff]]-Table1[[#This Row],[last_sheet_true_eff]] -> 0.98
A12: 11 | B12: 94.17 | C12: 97.77 | D12: 96.75 | E12: 94.33 | F12: 76.5 | G12: 86541 | H12: 1155214 | I12: 4 | K12: =Table1[[#This Row],[total_efficiency]]/Table1[[#This Row],[execution_time_ms]] -> 0.0010881547 | M12: =Table1[[#This Row],[total_waste_mm2]]/4 -> 288803.5 | O12: =Table1[[#This Row],[sheet_3_eff]]-Table1[[#This Row],[last_sheet_true_eff]] -> 17.83
A13: 12 | B13: 96.31 | C13: 97.77 | D13: 96.75 | E13: 95.1 | F13: 93.89 | G13: 86278 | H13: 1211014 | I13: 4 | K13: =Table1[[#This Row],[total_efficiency]]/Table1[[#This Row],[execution_time_ms]] -> 0.0011162753 | M13: =Table1[[#This Row],[total_waste_mm2]]/4 -> 302753.5 | O13: =Table1[[#This Row],[sheet_3_eff]]-Table1[[#This Row],[last_sheet_true_eff]] -> 1.21
... A51: 50 | B51: 95.19 | C51: 97.77 | D51: 96.12 | E51: 94.53 | F51: 86.4 | G51: 93221 | H51: 929224 | I51: 4 | K51: =Table1[[#This Row],[total_efficiency]]/Table1[[#This Row],[execution_time_ms]] -> 0.0010211219 | M51: =Table1[[#This Row],[total_waste_mm2]]/4 -> 232306 | O51: =Table1[[#This Row],[sheet_3_eff]]-Table1[[#This Row],[last_sheet_true_eff]] -> 8.13
A52: Max Eff preset ↑
A59: Fast Prd preset ↓
A61: run_id | B61: total_efficiency | C61: sheet_1_eff | D61: sheet_2_eff | E61: sheet_3_eff | F61: last_sheet_true_eff | G61: execution_time_ms | H61: total_waste_mm2 | I61: sheets_used | J61: Column1 | K61: Efficiency per ms | L61: Column2 | M61: Waste per sheet | N61: Column3 | O61: Efficiency drop on last sheet
A62: 1 | B62: 92.59 | C62: 97.42 | D62: 95.87 | E62: 89.71 | F62: 80.05 | G62: 97210 | H62: 1456534 | I62: 4 | K62: =Table10[[#This Row],[total_efficiency]]/Table10[[#This Row],[execution_time_ms]] -> 0.00095247403 | M62: =Table10[[#This Row],[total_waste_mm2]]/4 -> 364133.5 | O62: =Table10[[#This Row],[sheet_3_eff]]-Table10[[#This Row],[last_sheet_true_eff]] -> 9.66
A63: 2 | B63: 94.51 | C63: 97.4 | D63: 96.17 | E63: 92.28 | F63: 87.83 | G63: 98818 | H63: 1057564 | I63: 4 | K63: =Table10[[#This Row],[total_efficiency]]/Table10[[#This Row],[execution_time_ms]] -> 0.0009564047 | M63: =Table10[[#This Row],[total_waste_mm2]]/4 -> 264391 | O63: =Table10[[#This Row],[sheet_3_eff]]-Table10[[#This Row],[last_sheet_true_eff]] -> 4.45
A64: 3 | B64: 93.75 | C64: 93.99 | D64: 94.98 | E64: 95.03 | F64: 86.43 | G64: 121301 | H64: 1238914 | I64: 4 | K64: =Table10[[#This Row],[total_efficiency]]/Table10[[#This Row],[execution_time_ms]] -> 0.00077287079 | M64: =Table10[[#This Row],[total_waste_mm2]]/4 -> 309728.5 | O64: =Table10[[#This Row],[sheet_3_eff]]-Table10[[#This Row],[last_sheet_true_eff]] -> 8.6
A65: 4 | B65: 93.81 | C65: 96.85 | D65: 96.17 | E65: 93.16 | F65: 81.08 | G65: 114480 | H65: 1236124 | I65: 4 | K65: =Table10[[#This Row],[total_efficiency]]/Table10[[#This Row],[execution_time_ms]] -> 0.00081944444 | M65: =Table10[[#This Row],[total_waste_mm2]]/4 -> 309031 | O65: =Table10[[#This Row],[sheet_3_eff]]-Table10[[#This Row],[last_sheet_true_eff]] -> 12.08
A66: 5 | B66: 93.31 | C66: 96.52 | D66: 97.05 | E66: 90.41 | F66: 82.92 | G66: 108632 | H66: 1305874 | I66: 4 | K66: =Table10[[#This Row],[total_efficiency]]/Table10[[#This Row],[execution_time_ms]] -> 0.000858955 | M66: =Table10[[#This Row],[total_waste_mm2]]/4 -> 326468.5 | O66: =Table10[[#This Row],[sheet_3_eff]]-Table10[[#This Row],[last_sheet_true_eff]] -> 7.49
A67: 6 | B67: 92.76 | C67: 95.3 | D67: 94.21 | E67: 92.41 | F67: 83.89 | G67: 121674 | H67: 1660204 | I67: 4 | K67: =Table10[[#This Row],[total_efficiency]]/Table10[[#This Row],[execution_time_ms]] -> 0.00076236501 | M67: =Table10[[#This Row],[total_waste_mm2]]/4 -> 415051 | O67: =Table10[[#This Row],[sheet_3_eff]]-Table10[[#This Row],[last_sheet_true_eff]] -> 8.52
A68: 7 | B68: 93.31 | C68: 93.99 | D68: 95.34 | E68: 94.36 | F68: 83.7 | G68: 122558 | H68: 1361674 | I68: 4 | K68: =Table10[[#This Row],[total_efficiency]]/Table10[[#This Row],[execution_time_ms]] -> 0.00076135381 | M68: =Table10[[#This Row],[total_waste_mm2]]/4 -> 340418.5 | O68: =Table10[[#This Row],[sheet_3_eff]]-Table10[[#This Row],[last_sheet_true_eff]] -> 10.66
A69: 8 | B69: 93.85 | C69: 96.56 | D69: 95.08 | E69: 94.49 | F69: 81.51 | G69: 120299 | H69: 1205434 | I69: 4 | K69: =Table10[[#This Row],[total_efficiency]]/Table10[[#This Row],[execution_time_ms]] -> 0.00078013949 | M69: =Table10[[#This Row],[total_waste_mm2]]/4 -> 301358.5 | O69: =Table10[[#This Row],[sheet_3_eff]]-Table10[[#This Row],[last_sheet_true_eff]] -> 12.98
A70: 9 | B70: 94.31 | C70: 94.97 | D70: 94.82 | E70: 95.39 | F70: 87.94 | G70: 127753 | H70: 1102204 | I70: 4 | K70: =Table10[[#This Row],[total_efficiency]]/Table10[[#This Row],[execution_time_ms]] -> 0.00073822141 | M70: =Table10[[#This Row],[total_waste_mm2]]/4 -> 275551 | O70: =Table10[[#This Row],[sheet_3_eff]]-Table10[[#This Row],[last_sheet_true_eff]] -> 7.45
A71: 10 | B71: 93.61 | C71: 93.99 | D71: 95.31 | E71: 95.65 | F71: 82.79 | G71: 116738 | H71: 1289134 | I71: 4 | K71: =Table10[[#This Row],[total_efficiency]]/Table10[[#This Row],[execution_time_ms]] -> 0.00080188114 | M71: =Table10[[#This Row],[total_waste_mm2]]/4 -> 322283.5 | O71: =Table10[[#This Row],[sheet_3_eff]]-Table10[[#This Row],[last_sheet_true_eff]] -> 12.86
A72: 11 | B72: 93.35 | C72: 96.56 | D72: 96.58 | E72: 93.29 | F72: 76.93 | G72: 110398 | H72: 1333774 | I72: 4 | K72: =Table10[[#This Row],[total_efficiency]]/Table10[[#This Row],[execution_time_ms]] -> 0.00084557691 | M72: =Table10[[#This Row],[total_waste_mm2]]/4 -> 333443.5 | O72: =Table10[[#This Row],[sheet_3_eff]]-Table10[[#This Row],[last_sheet_true_eff]] -> 16.36
A73: 12 | B73: 93.49 | C73: 96.02 | D73: 95.14 | E73: 92.18 | F73: 86.05 | G73: 114355 | H73: 1289134 | I73: 4 | K73: =Table10[[#This Row],[total_efficiency]]/Table10[[#This Row],[execution_time_ms]] -> 0.00081754187 | M73: =Table10[[#This Row],[total_waste_mm2]]/4 -> 322283.5 | O73: =Table10[[#This Row],[sheet_3_eff]]-Table10[[#This Row],[last_sheet_true_eff]] -> 6.13
... A111: 50 | B111: 94.78 | C111: 95.89 | D111: 95.93 | E111: 94.28 | F111: 89.54 | G111: 109956 | H111: 1068724 | I111: 4 | K111: =Table10[[#This Row],[total_efficiency]]/Table10[[#This Row],[execution_time_ms]] -> 0.00086198116 | M111: =Table10[[#This Row],[total_waste_mm2]]/4 -> 267181 | O111: =Table10[[#This Row],[sheet_3_eff]]-Table10[[#This Row],[last_sheet_true_eff]] -> 4.74
A118: Balanced preset ↓
A120: run_id | B120: total_efficiency | C120: sheet_1_eff | D120: sheet_2_eff | E120: sheet_3_eff | F120: last_sheet_true_eff | G120: execution_time_ms | H120: total_waste_mm2 | I120: sheets_used | J120: Column1 | K120: Efficiency per ms | L120: Column2 | M120: Waste per sheet | N120: Column3 | O120: Efficiency drop on last sheet
A121: 1 | B121: 95.39 | C121: 97.62 | D121: 95.53 | E121: 94.39 | F121: 91.05 | G121: 106727 | H121: 934804 | I121: 4 | K121: =Table1042[[#This Row],[total_efficiency]]/Table1042[[#This Row],[execution_time_ms]] -> 0.00089377571 | M121: =Table1042[[#This Row],[total_waste_mm2]]/4 -> 233701 | O121: =Table1042[[#This Row],[sheet_3_eff]]-Table1042[[#This Row],[last_sheet_true_eff]] -> 3.34
A122: 2 | B122: 95.36 | C122: 96.52 | D122: 97.05 | E122: 94.12 | F122: 90.3 | G122: 131923 | H122: 934804 | I122: 4 | K122: =Table1042[[#This Row],[total_efficiency]]/Table1042[[#This Row],[execution_time_ms]] -> 0.0007228459 | M122: =Table1042[[#This Row],[total_waste_mm2]]/4 -> 233701 | O122: =Table1042[[#This Row],[sheet_3_eff]]-Table1042[[#This Row],[last_sheet_true_eff]] -> 3.82
A123: 3 | B123: 93.02 | C123: 97.62 | D123: 95.82 | E123: 90.58 | F123: 80.62 | G123: 123811 | H123: 1378414 | I123: 4 | K123: =Table1042[[#This Row],[total_efficiency]]/Table1042[[#This Row],[execution_time_ms]] -> 0.00075130643 | M123: =Table1042[[#This Row],[total_waste_mm2]]/4 -> 344603.5 | O123: =Table1042[[#This Row],[sheet_3_eff]]-Table1042[[#This Row],[last_sheet_true_eff]] -> 9.96
A124: 4 | B124: 93.39 | C124: 97.07 | D124: 94.35 | E124: 91.2 | F124: 87.07 | G124: 108212 | H124: 1294714 | I124: 4 | K124: =Table1042[[#This Row],[total_efficiency]]/Table1042[[#This Row],[execution_time_ms]] -> 0.00086302813 | M124: =Table1042[[#This Row],[total_waste_mm2]]/4 -> 323678.5 | O124: =Table1042[[#This Row],[sheet_3_eff]]-Table1042[[#This Row],[last_sheet_true_eff]] -> 4.13
A125: 5 | B125: 95.06 | C125: 97.07 | D125: 94.35 | E125: 94.25 | F125: 93.61 | G125: 219432 | H125: 1294714 | I125: 4 | K125: =Table1042[[#This Row],[total_efficiency]]/Table1042[[#This Row],[execution_time_ms]] -> 0.00043320938 | M125: =Table1042[[#This Row],[total_waste_mm2]]/4 -> 323678.5 | O125: =Table1042[[#This Row],[sheet_3_eff]]-Table1042[[#This Row],[last_sheet_true_eff]] -> 0.64
A126: 6 | B126: 95.42 | C126: 97.42 | D126: 96.15 | E126: 94.04 | F126: 91.17 | G126: 104971 | H126: 887374 | I126: 4 | K126: =Table1042[[#This Row],[total_efficiency]]/Table1042[[#This Row],[execution_time_ms]] -> 0.00090901297 | M126: =Table1042[[#This Row],[total_waste_mm2]]/4 -> 221843.5 | O126: =Table1042[[#This Row],[sheet_3_eff]]-Table1042[[#This Row],[last_sheet_true_eff]] -> 2.87
A127: 7 | B127: 95.17 | C127: 97.29 | D127: 96.96 | E127: 94.2 | F127: 86.09 | G127: 131887 | H127: 934804 | I127: 4 | K127: =Table1042[[#This Row],[total_efficiency]]/Table1042[[#This Row],[execution_time_ms]] -> 0.00072160258 | M127: =Table1042[[#This Row],[total_waste_mm2]]/4 -> 233701 | O127: =Table1042[[#This Row],[sheet_3_eff]]-Table1042[[#This Row],[last_sheet_true_eff]] -> 8.11
A128: 8 | B128: 95.16 | C128: 96.73 | D128: 97.13 | E128: 93.03 | F128: 90.79 | G128: 226695 | H128: 985024 | I128: 4 | K128: =Table1042[[#This Row],[total_efficiency]]/Table1042[[#This Row],[execution_time_ms]] -> 0.00041977106 | M128: =Table1042[[#This Row],[total_waste_mm2]]/4 -> 246256 | O128: =Table1042[[#This Row],[sheet_3_eff]]-Table1042[[#This Row],[last_sheet_true_eff]] -> 2.24
...

Sheet podaci
A1: run | B1: efikasnost_% | C1: ploca_1_% | D1: ploca_2_% | E1: ploca_3_% | F1: zadnja_ploca_% | G1: vrijeme_s | H1: otpad_m2 | I1: pad_zadnje_% | R1: Helper | S1: run | T1: pad_zadnje_%
A2: =raw_podaci!A2 -> 1 | B2: =raw_podaci!B2 -> 95.24 | C2: =raw_podaci!C2 -> 97.77 | D2: =raw_podaci!D2 -> 96.75 | E2: =raw_podaci!E2 -> 94.17 | F2: =raw_podaci!F2 -> 85.98 | G2: =raw_podaci!G2/1000 -> 91.74 | H2: =raw_podaci!H2/1000000 -> 0.934804 | I2: =raw_podaci!O2 -> 8.19 | R2: Sorted> | S2: =raw_podaci!A11 -> 10 | T2: =raw_podaci!O11 -> 0.98
A3: =raw_podaci!A3 -> 2 | B3: =raw_podaci!B3 -> 95.13 | C3: =raw_podaci!C3 -> 97.77 | D3: =raw_podaci!D3 -> 96.57 | E3: =raw_podaci!E3 -> 92.36 | F3: =raw_podaci!F3 -> 91.15 | G3: =raw_podaci!G3/1000 -> 187.938 | H3: =raw_podaci!H3/1000000 -> 0.934804 | I3: =raw_podaci!O3 -> 1.21 | S3: =raw_podaci!A3 -> 2 | T3: =raw_podaci!O3 -> 1.21
A4: =raw_podaci!A4 -> 3 | B4: =raw_podaci!B4 -> 95.45 | C4: =raw_podaci!C4 -> 97.77 | D4: =raw_podaci!D4 -> 96.08 | E4: =raw_podaci!E4 -> 94.96 | F4: =raw_podaci!F4 -> 87.61 | G4: =raw_podaci!G4/1000 -> 188.765 | H4: =raw_podaci!H4/1000000 -> 0.985024 | I4: =raw_podaci!O4 -> 7.35 | S4: =raw_podaci!A13 -> 12 | T4: =raw_podaci!O13 -> 1.21
A5: =raw_podaci!A5 -> 4 | B5: =raw_podaci!B5 -> 94.17 | C5: =raw_podaci!C5 -> 97.77 | D5: =raw_podaci!D5 -> 95.98 | E5: =raw_podaci!E5 -> 95.8 | F5: =raw_podaci!F5 -> 74.54 | G5: =raw_podaci!G5/1000 -> 85.793 | H5: =raw_podaci!H5/1000000 -> 1.155214 | I5: =raw_podaci!O5 -> 21.26 | S5: =raw_podaci!A14 -> 13 | T5: =raw_podaci!O14 -> 1.21
A6: =raw_podaci!A6 -> 5 | B6: =raw_podaci!B6 -> 95.12 | C6: =raw_podaci!C6 -> 97.77 | D6: =raw_podaci!D6 -> 96.42 | E6: =raw_podaci!E6 -> 94.02 | F6: =raw_podaci!F6 -> 86.38 | G6: =raw_podaci!G6/1000 -> 92.514 | H6: =raw_podaci!H6/1000000 -> 0.934804 | I6: =raw_podaci!O6 -> 7.64 | S6: =raw_podaci!A46 -> 45 | T6: =raw_podaci!O46 -> 1.21
A7: =raw_podaci!A7 -> 6 | B7: =raw_podaci!B7 -> 94.4 | C7: =raw_podaci!C7 -> 97.77 | D7: =raw_podaci!D7 -> 96.35 | E7: =raw_podaci!E7 -> 95.1 | F7: =raw_podaci!F7 -> 77.3 | G7: =raw_podaci!G7/1000 -> 91.662 | H7: =raw_podaci!H7/1000000 -> 1.104994 | I7: =raw_podaci!O7 -> 17.8 | S7: =raw_podaci!A27 -> 26 | T7: =raw_podaci!O27 -> 1.82
A8: =raw_podaci!A8 -> 7 | B8: =raw_podaci!B8 -> 93.86 | C8: =raw_podaci!C8 -> 97.77 | D8: =raw_podaci!D8 -> 95.78 | E8: =raw_podaci!E8 -> 94.38 | F8: =raw_podaci!F8 -> 76.7 | G8: =raw_podaci!G8/1000 -> 86.366 | H8: =raw_podaci!H8/1000000 -> 1.205434 | I8: =raw_podaci!O8 -> 17.68 | S8: =raw_podaci!A45 -> 44 | T8: =raw_podaci!O45 -> 3.21
A9: =raw_podaci!A9 -> 8 | B9: =raw_podaci!B9 -> 95.9 | C9: =raw_podaci!C9 -> 97.77 | D9: =raw_podaci!D9 -> 96.75 | E9: =raw_podaci!E9 -> 95.36 | F9: =raw_podaci!F9 -> 88.65 | G9: =raw_podaci!G9/1000 -> 86.375 | H9: =raw_podaci!H9/1000000 -> 0.884584 | I9: =raw_podaci!O9 -> 6.71 | S9: =raw_podaci!A38 -> 37 | T9: =raw_podaci!O38 -> 3.5
A10: =raw_podaci!A10 -> 9 | B10: =raw_podaci!B10 -> 95.9 | C10: =raw_podaci!C10 -> 97.77 | D10: =raw_podaci!D10 -> 96.75 | E10: =raw_podaci!E10 -> 95.36 | F10: =raw_podaci!F10 -> 88.65 | G10: =raw_podaci!G10/1000 -> 86.806 | H10: =raw_podaci!H10/1000000 -> 0.884584 | I10: =raw_podaci!O10 -> 6.71 | S10: =raw_podaci!A26 -> 25 | T10: =raw_podaci!O26 -> 4.18
A11: =raw_podaci!A11 -> 10 | B11: =raw_podaci!B11 -> 96.32 | C11: =raw_podaci!C11 -> 97.77 | D11: =raw_podaci!D11 -> 96.67 | E11: =raw_podaci!E11 -> 95.14 | F11: =raw_podaci!F11 -> 94.16 | G11: =raw_podaci!G11/1000 -> 86.498 | H11: =raw_podaci!H11/1000000 -> 0.733924 | I11: =raw_podaci!O11 -> 0.98 | S11: =raw_podaci!A18 -> 17 | T11: =raw_podaci!O18 -> 4.19
A12: =raw_podaci!A12 -> 11 | B12: =raw_podaci!B12 -> 94.17 | C12: =raw_podaci!C12 -> 97.77 | D12: =raw_podaci!D12 -> 96.75 | E12: =raw_podaci!E12 -> 94.33 | F12: =raw_podaci!F12 -> 76.5 | G12: =raw_podaci!G12/1000 -> 86.541 | H12: =raw_podaci!H12/1000000 -> 1.155214 | I12: =raw_podaci!O12 -> 17.83 | S12: =raw_podaci!A16 -> 15 | T12: =raw_podaci!O16 -> 5.26
A13: =raw_podaci!A13 -> 12 | B13: =raw_podaci!B13 -> 96.31 | C13: =raw_podaci!C13 -> 97.77 | D13: =raw_podaci!D13 -> 96.75 | E13: =raw_podaci!E13 -> 95.1 | F13: =raw_podaci!F13 -> 93.89 | G13: =raw_podaci!G13/1000 -> 86.278 | H13: =raw_podaci!H13/1000000 -> 1.211014 | I13: =raw_podaci!O13 -> 1.21 | S13: =raw_podaci!A42 -> 41 | T13: =raw_podaci!O42 -> 5.32
A14: =raw_podaci!A14 -> 13 | B14: =raw_podaci!B14 -> 96.31 | C14: =raw_podaci!C14 -> 97.77 | D14: =raw_podaci!D14 -> 96.75 | E14: =raw_podaci!E14 -> 95.1 | F14: =raw_podaci!F14 -> 93.89 | G14: =raw_podaci!G14/1000 -> 86.061 | H14: =raw_podaci!H14/1000000 -> 1.211014 | I14: =raw_podaci!O14 -> 1.21 | S14: =raw_podaci!A30 -> 29 | T14: =raw_podaci!O30 -> 6.04
A15: =raw_podaci!A15 -> 14 | B15: =raw_podaci!B15 -> 95.35 | C15: =raw_podaci!C15 -> 97.77 | D15: =raw_podaci!D15 -> 96.02 | E15: =raw_podaci!E15 -> 96.08 | F15: =raw_podaci!F15 -> 83.3 | G15: =raw_podaci!G15/1000 -> 183.913 | H15: =raw_podaci!H15/1000000 -> 0.887374 | I15: =raw_podaci!O15 -> 12.78 | S15: =raw_podaci!A23 -> 22 | T15: =raw_podaci!O23 -> 6.26
A16: =raw_podaci!A16 -> 15 | B16: =raw_podaci!B16 -> 95.31 | C16: =raw_podaci!C16 -> 97.77 | D16: =raw_podaci!D16 -> 96.56 | E16: =raw_podaci!E16 -> 93.78 | F16: =raw_podaci!F16 -> 88.52 | G16: =raw_podaci!G16/1000 -> 92.309 | H16: =raw_podaci!H16/1000000 -> 0.934804 | I16: =raw_podaci!O16 -> 5.26 | S16: =raw_podaci!A37 -> 36 | T16: =raw_podaci!O37 -> 6.29
A17: =raw_podaci!A17 -> 16 | B17: =raw_podaci!B17 -> 94.83 | C17: =raw_podaci!C17 -> 97.4 | D17: =raw_podaci!D17 -> 96.31 | E17: =raw_podaci!E17 -> 96.06 | F17: =raw_podaci!F17 -> 79.12 | G17: =raw_podaci!G17/1000 -> 88.684 | H17: =raw_podaci!H17/1000000 -> 1.138474 | I17: =raw_podaci!O17 -> 16.94 | S17: =raw_podaci!A34 -> 33 | T17: =raw_podaci!O34 -> 6.59
A18: =raw_podaci!A18 -> 17 | B18: =raw_podaci!B18 -> 95.15 | C18: =raw_podaci!C18 -> 97.77 | D18: =raw_podaci!D18 -> 95.91 | E18: =raw_podaci!E18 -> 93.62 | F18: =raw_podaci!F18 -> 89.43 | G18: =raw_podaci!G18/1000 -> 93.069 | H18: =raw_podaci!H18/1000000 -> 0.934804 | I18: =raw_podaci!O18 -> 4.19 | S18: =raw_podaci!A9 -> 8 | T18: =raw_podaci!O9 -> 6.71
A19: =raw_podaci!A19 -> 18 | B19: =raw_podaci!B19 -> 95.16 | C19: =raw_podaci!C19 -> 97.75 | D19: =raw_podaci!D19 -> 96.78 | E19: =raw_podaci!E19 -> 94.52 | F19: =raw_podaci!F19 -> 84.17 | G19: =raw_podaci!G19/1000 -> 91.677 | H19: =raw_podaci!H19/1000000 -> 0.934804 | I19: =raw_podaci!O19 -> 10.35 | S19: =raw_podaci!A10 -> 9 | T19: =raw_podaci!O10 -> 6.71
A20: =raw_podaci!A20 -> 19 | B20: =raw_podaci!B20 -> 95.1 | C20: =raw_podaci!C20 -> 97.77 | D20: =raw_podaci!D20 -> 95.8 | E20: =raw_podaci!E20 -> 94.69 | F20: =raw_podaci!F20 -> 86.01 | G20: =raw_podaci!G20/1000 -> 94.971 | H20: =raw_podaci!H20/1000000 -> 1.160794 | I20: =raw_podaci!O20 -> 8.68 | S20: =raw_podaci!A21 -> 20 | T20: =raw_podaci!O21 -> 6.71
A21: =raw_podaci!A21 -> 20 | B21: =raw_podaci!B21 -> 95.9 | C21: =raw_podaci!C21 -> 97.77 | D21: =raw_podaci!D21 -> 96.75 | E21: =raw_podaci!E21 -> 95.36 | F21: =raw_podaci!F21 -> 88.65 | G21: =raw_podaci!G21/1000 -> 86.867 | H21: =raw_podaci!H21/1000000 -> 0.884584 | I21: =raw_podaci!O21 -> 6.71 | S21: =raw_podaci!A29 -> 28 | T21: =raw_podaci!O29 -> 6.71
A22: =raw_podaci!A22 -> 21 | B22: =raw_podaci!B22 -> 94.47 | C22: =raw_podaci!C22 -> 97.77 | D22: =raw_podaci!D22 -> 96.89 | E22: =raw_podaci!E22 -> 94.97 | F22: =raw_podaci!F22 -> 76.63 | G22: =raw_podaci!G22/1000 -> 91.49 | H22: =raw_podaci!H22/1000000 -> 1.104994 | I22: =raw_podaci!O22 -> 18.34 | S22: =raw_podaci!A4 -> 3 | T22: =raw_podaci!O4 -> 7.35
A23: =raw_podaci!A23 -> 22 | B23: =raw_podaci!B23 -> 95.04 | C23: =raw_podaci!C23 -> 97.77 | D23: =raw_podaci!D23 -> 96.16 | E23: =raw_podaci!E23 -> 93.7 | F23: =raw_podaci!F23 -> 87.44 | G23: =raw_podaci!G23/1000 -> 87.438 | H23: =raw_podaci!H23/1000000 -> 1.205434 | I23: =raw_podaci!O23 -> 6.26 | S23: =raw_podaci!A24 -> 23 | T23: =raw_podaci!O24 -> 7.59
A24: =raw_podaci!A24 -> 23 | B24: =raw_podaci!B24 -> 96.42 | C24: =raw_podaci!C24 -> 97.62 | D24: =raw_podaci!D24 -> 96.75 | E24: =raw_podaci!E24 -> 96.89 | F24: =raw_podaci!F24 -> 89.3 | G24: =raw_podaci!G24/1000 -> 88.328 | H24: =raw_podaci!H24/1000000 -> 0.697654 | I24: =raw_podaci!O24 -> 7.59 | S24: =raw_podaci!A32 -> 31 | T24: =raw_podaci!O32 -> 7.59
A25: =raw_podaci!A25 -> 24 | B25: =raw_podaci!B25 -> 95.21 | C25: =raw_podaci!C25 -> 97.77 | D25: =raw_podaci!D25 -> 96.06 | E25: =raw_podaci!E25 -> 94.67 | F25: =raw_podaci!F25 -> 86.31 | G25: =raw_podaci!G25/1000 -> 196.476 | H25: =raw_podaci!H25/1000000 -> 0.934804 | I25: =raw_podaci!O25 -> 8.36 | S25: =raw_podaci!A50 -> 49 | T25: =raw_podaci!O50 -> 7.63
A26: =raw_podaci!A26 -> 25 | B26: =raw_podaci!B26 -> 95.22 | C26: =raw_podaci!C26 -> 97.77 | D26: =raw_podaci!D26 -> 96.01 | E26: =raw_podaci!E26 -> 93.72 | F26: =raw_podaci!F26 -> 89.54 | G26: =raw_podaci!G26/1000 -> 105.034 | H26: =raw_podaci!H26/1000000 -> 0.929224 | I26: =raw_podaci!O26 -> 4.18 | S26: =raw_podaci!A6 -> 5 | T26: =raw_podaci!O6 -> 7.64
A27: =raw_podaci!A27 -> 26 | B27: =raw_podaci!B27 -> 95.52 | C27: =raw_podaci!C27 -> 97.77 | D27: =raw_podaci!D27 -> 96.28 | E27: =raw_podaci!E27 -> 93.66 | F27: =raw_podaci!F27 -> 91.84 | G27: =raw_podaci!G27/1000 -> 211.016 | H27: =raw_podaci!H27/1000000 -> 0.859474 | I27: =raw_podaci!O27 -> 1.82 | S27: =raw_podaci!A51 -> 50 | T27: =raw_podaci!O51 -> 8.13
A28: =raw_podaci!A28 -> 27 | B28: =raw_podaci!B28 -> 93.72 | C28: =raw_podaci!C28 -> 97.77 | D28: =raw_podaci!D28 -> 95.88 | E28: =raw_podaci!E28 -> 92.87 | F28: =raw_podaci!F28 -> 79.4 | G28: =raw_podaci!G28/1000 -> 94.963 | H28: =raw_podaci!H28/1000000 -> 1.238914 | I28: =raw_podaci!O28 -> 13.47 | S28: =raw_podaci!A2 -> 1 | T28: =raw_podaci!O2 -> 8.19
A29: =raw_podaci!A29 -> 28 | B29: =raw_podaci!B29 -> 95.9 | C29: =raw_podaci!C29 -> 97.77 | D29: =raw_podaci!D29 -> 96.75 | E29: =raw_podaci!E29 -> 95.36 | F29: =raw_podaci!F29 -> 88.65 | G29: =raw_podaci!G29/1000 -> 86.284 | H29: =raw_podaci!H29/1000000 -> 0.884584 | I29: =raw_podaci!O29 -> 6.71 | S29: =raw_podaci!A25 -> 24 | T29: =raw_podaci!O25 -> 8.36
A30: =raw_podaci!A30 -> 29 | B30: =raw_podaci!B30 -> 95.35 | C30: =raw_podaci!C30 -> 97.77 | D30: =raw_podaci!D30 -> 96.38 | E30: =raw_podaci!E30 -> 94.19 | F30: =raw_podaci!F30 -> 88.15 | G30: =raw_podaci!G30/1000 -> 91.413 | H30: =raw_podaci!H30/1000000 -> 0.934804 | I30: =raw_podaci!O30 -> 6.04 | S30: =raw_podaci!A39 -> 38 | T30: =raw_podaci!O39 -> 8.61
A31: =raw_podaci!A31 -> 30 | B31: =raw_podaci!B31 -> 94.01 | C31: =raw_podaci!C31 -> 97.77 | D31: =raw_podaci!D31 -> 96.09 | E31: =raw_podaci!E31 -> 94.03 | F31: =raw_podaci!F31 -> 77.94 | G31: =raw_podaci!G31/1000 -> 94.446 | H31: =raw_podaci!H31/1000000 -> 1.389574 | I31: =raw_podaci!O31 -> 16.09 | S31: =raw_podaci!A20 -> 19 | T31: =raw_podaci!O20 -> 8.68
A32: =raw_podaci!A32 -> 31 | B32: =raw_podaci!B32 -> 96.42 | C32: =raw_podaci!C32 -> 97.62 | D32: =raw_podaci!D32 -> 96.75 | E32: =raw_podaci!E32 -> 96.89 | F32: =raw_podaci!F32 -> 89.3 | G32: =raw_podaci!G32/1000 -> 87.679 | H32: =raw_podaci!H32/1000000 -> 0.697654 | I32: =raw_podaci!O32 -> 7.59 | S32: =raw_podaci!A36 -> 35 | T32: =raw_podaci!O36 -> 8.69
A33: =raw_podaci!A33 -> 32 | B33: =raw_podaci!B33 -> 94.1 | C33: =raw_podaci!C33 -> 97.77 | D33: =raw_podaci!D33 -> 96.49 | E33: =raw_podaci!E33 -> 93.44 | F33: =raw_podaci!F33 -> 79.15 | G33: =raw_podaci!G33/1000 -> 89.401 | H33: =raw_podaci!H33/1000000 -> 1.205434 | I33: =raw_podaci!O33 -> 14.29 | S33: =raw_podaci!A49 -> 48 | T33: =raw_podaci!O49 -> 8.91
A34: =raw_podaci!A34 -> 33 | B34: =raw_podaci!B34 -> 95.9 | C34: =raw_podaci!C34 -> 97.77 | D34: =raw_podaci!D34 -> 96.75 | E34: =raw_podaci!E34 -> 95.33 | F34: =raw_podaci!F34 -> 88.74 | G34: =raw_podaci!G34/1000 -> 86.36 | H34: =raw_podaci!H34/1000000 -> 0.884584 | I34: =raw_podaci!O34 -> 6.59 | S34: =raw_podaci!A40 -> 39 | T34: =raw_podaci!O40 -> 9.15
A35: =raw_podaci!A35 -> 34 | B35: =raw_podaci!B35 -> 93.68 | C35: =raw_podaci!C35 -> 97.77 | D35: =raw_podaci!D35 -> 96.56 | E35: =raw_podaci!E35 -> 94.27 | F35: =raw_podaci!F35 -> 73.59 | G35: =raw_podaci!G35/1000 -> 91.189 | H35: =raw_podaci!H35/1000000 -> 1.389574 | I35: =raw_podaci!O35 -> 20.68 | S35: =raw_podaci!A19 -> 18 | T35: =raw_podaci!O19 -> 10.35
A36: =raw_podaci!A36 -> 35 | B36: =raw_podaci!B36 -> 95.08 | C36: =raw_podaci!C36 -> 97.77 | D36: =raw_podaci!D36 -> 95.82 | E36: =raw_podaci!E36 -> 94.65 | F36: =raw_podaci!F36 -> 85.96 | G36: =raw_podaci!G36/1000 -> 89.484 | H36: =raw_podaci!H36/1000000 -> 1.138474 | I36: =raw_podaci!O36 -> 8.69 | S36: =raw_podaci!A47 -> 46 | T36: =raw_podaci!O47 -> 10.37
A37: =raw_podaci!A37 -> 36 | B37: =raw_podaci!B37 -> 95.81 | C37: =raw_podaci!C37 -> 97.77 | D37: =raw_podaci!D37 -> 96.49 | E37: =raw_podaci!E37 -> 95.25 | F37: =raw_podaci!F37 -> 88.96 | G37: =raw_podaci!G37/1000 -> 84.179 | H37: =raw_podaci!H37/1000000 -> 0.887374 | I37: =raw_podaci!O37 -> 6.29 | S37: =raw_podaci!A43 -> 42 | T37: =raw_podaci!O43 -> 10.83
A38: =raw_podaci!A38 -> 37 | B38: =raw_podaci!B38 -> 95.35 | C38: =raw_podaci!C38 -> 97.77 | D38: =raw_podaci!D38 -> 95.56 | E38: =raw_podaci!E38 -> 94.2 | F38: =raw_podaci!F38 -> 90.7 | G38: =raw_podaci!G38/1000 -> 88.929 | H38: =raw_podaci!H38/1000000 -> 0.934804 | I38: =raw_podaci!O38 -> 3.5 | S38: =raw_podaci!A15 -> 14 | T38: =raw_podaci!O15 -> 12.78
A39: =raw_podaci!A39 -> 38 | B39: =raw_podaci!B39 -> 94.37 | C39: =raw_podaci!C39 -> 97.77 | D39: =raw_podaci!D39 -> 96.12 | E39: =raw_podaci!E39 -> 92.81 | F39: =raw_podaci!F39 -> 84.2 | G39: =raw_podaci!G39/1000 -> 88.661 | H39: =raw_podaci!H39/1000000 -> 1.205434 | I39: =raw_podaci!O39 -> 8.61 | S39: =raw_podaci!A44 -> 43 | T39: =raw_podaci!O44 -> 13.36
A40: =raw_podaci!A40 -> 39 | B40: =raw_podaci!B40 -> 95.35 | C40: =raw_podaci!C40 -> 97.77 | D40: =raw_podaci!D40 -> 95.82 | E40: =raw_podaci!E40 -> 95.36 | F40: =raw_podaci!F40 -> 86.21 | G40: =raw_podaci!G40/1000 -> 92.346 | H40: =raw_podaci!H40/1000000 -> 0.929224 | I40: =raw_podaci!O40 -> 9.15 | S40: =raw_podaci!A28 -> 27 | T40: =raw_podaci!O28 -> 13.47
...

Sheet statistika
A1: metrika | B1: min | C1: q1 | D1: medijan | E1: prosjek | F1: q3 | G1: max | H1: st_dev
A2: ukupna efikasnost (%) | B2: =MIN(podaci!B2:B51) -> 93.68 | C2: =QUARTILE(podaci!B2:B51,1) -> 94.47 | D2: =MEDIAN(podaci!B2:B51) -> 95.185 | E2: =AVERAGE(podaci!B2:B51) -> 95.1094 | F2: =QUARTILE(podaci!B2:B51,3) -> 95.595 | G2: =MAX(podaci!B2:B51) -> 96.42 | H2: =STDEV(podaci!B2:B51) -> 0.77044755
A3: ploča 1 (%) | B3: =MIN(podaci!C2:C51) -> 97.4 | C3: =QUARTILE(podaci!C2:C51,1) -> 97.77 | D3: =MEDIAN(podaci!C2:C51) -> 97.77 | E3: =AVERAGE(podaci!C2:C51) -> 97.7502 | F3: =QUARTILE(podaci!C2:C51,3) -> 97.77 | G3: =MAX(podaci!C2:C51) -> 97.77 | H3: =STDEV(podaci!C2:C51) -> 0.065105566
A4: ploča 2 (%) | B4: =MIN(podaci!D2:D51) -> 95.56 | C4: =QUARTILE(podaci!D2:D51,1) -> 96.0125 | D4: =MEDIAN(podaci!D2:D51) -> 96.455 | E4: =AVERAGE(podaci!D2:D51) -> 96.3534 | F4: =QUARTILE(podaci!D2:D51,3) -> 96.75 | G4: =MAX(podaci!D2:D51) -> 96.89 | H4: =STDEV(podaci!D2:D51) -> 0.37391809
A5: ploča 3 (%) | B5: =MIN(podaci!E2:E51) -> 91.99 | C5: =QUARTILE(podaci!E2:E51,1) -> 93.975 | D5: =MEDIAN(podaci!E2:E51) -> 94.525 | E5: =AVERAGE(podaci!E2:E51) -> 94.5254 | F5: =QUARTILE(podaci!E2:E51,3) -> 95.13 | G5: =MAX(podaci!E2:E51) -> 96.89 | H5: =STDEV(podaci!E2:E51) -> 1.023434
A6: zadnja ploča (%) | B6: =MIN(podaci!F2:F51) -> 73.59 | C6: =QUARTILE(podaci!F2:F51,1) -> 80.57 | D6: =MEDIAN(podaci!F2:F51) -> 86.39 | E6: =AVERAGE(podaci!F2:F51) -> 85.332 | F6: =QUARTILE(podaci!F2:F51,3) -> 88.915 | G6: =MAX(podaci!F2:F51) -> 94.16 | H6: =STDEV(podaci!F2:F51) -> 5.5731052
A7: pad zadnje ploče (%) | B7: =MIN(podaci!I2:I51) -> 0.98 | C7: =QUARTILE(podaci!I2:I51,1) -> 6.095 | D7: =MEDIAN(podaci!I2:I51) -> 7.885 | E7: =AVERAGE(podaci!I2:I51) -> 9.1934 | F7: =QUARTILE(podaci!I2:I51,3) -> 13.215 | G7: =MAX(podaci!I2:I51) -> 21.26 | H7: =STDEV(podaci!I2:I51) -> 5.573639
A8: vrijeme (s) | B8: =MIN(podaci!G2:G51) -> 84.179 | C8: =QUARTILE(podaci!G2:G51,1) -> 87.49825 | D8: =MEDIAN(podaci!G2:G51) -> 91.2515 | E8: =AVERAGE(podaci!G2:G51) -> 108.7204 | F8: =QUARTILE(podaci!G2:G51,3) -> 94.83375 | G8: =MAX(podaci!G2:G51) -> 211.016 | H8: =STDEV(podaci!G2:G51) -> 40.543812
A9: otpad (m²) | B9: =MIN(podaci!H2:H51) -> 0.697654 | C9: =QUARTILE(podaci!H2:H51,1) -> 0.929224 | D9: =MEDIAN(podaci!H2:H51) -> 0.934804 | E9: =AVERAGE(podaci!H2:H51) -> 1.0280458 | F9: =QUARTILE(podaci!H2:H51,3) -> 1.159399 | G9: =MAX(podaci!H2:H51) -> 1.389574 | H9: =STDEV(podaci!H2:H51) -> 0.165077
A10: Max Eff preset ↑
A61: metrika | B61: min | C61: q1 | D61: medijan | E61: prosjek | F61: q3 | G61: max | H61: st_dev
A62: ukupna efikasnost (%) | B62: =MIN(podaci!B62:B111) -> 92.3 | C62: =QUARTILE(podaci!B62:B111,1) -> 93.52 | D62: =MEDIAN(podaci!B62:B111) -> 93.945 | E62: =AVERAGE(podaci!B62:B111) -> 93.9772 | F62: =QUARTILE(podaci!B62:B111,3) -> 94.4925 | G62: =MAX(podaci!B62:B111) -> 95.64 | H62: =STDEV(podaci!B62:B111) -> 0.70824313
A63: ploča 1 (%) | B63: =MIN(podaci!C62:C111) -> 93.99 | C63: =QUARTILE(podaci!C62:C111,1) -> 95.33 | D63: =MEDIAN(podaci!C62:C111) -> 96.545 | E63: =AVERAGE(podaci!C62:C111) -> 96.2416 | F63: =QUARTILE(podaci!C62:C111,3) -> 97.1375 | G63: =MAX(podaci!C62:C111) -> 97.42 | H63: =STDEV(podaci!C62:C111) -> 1.0975917
A64: ploča 2 (%) | B64: =MIN(podaci!D62:D111) -> 93.53 | C64: =QUARTILE(podaci!D62:D111,1) -> 94.84 | D64: =MEDIAN(podaci!D62:D111) -> 95.8 | E64: =AVERAGE(podaci!D62:D111) -> 95.576 | F64: =QUARTILE(podaci!D62:D111,3) -> 96.2225 | G64: =MAX(podaci!D62:D111) -> 97.05 | H64: =STDEV(podaci!D62:D111) -> 0.90793778
A65: ploča 3 (%) | B65: =MIN(podaci!E62:E111) -> 89.71 | C65: =QUARTILE(podaci!E62:E111,1) -> 92.4275 | D65: =MEDIAN(podaci!E62:E111) -> 93.255 | E65: =AVERAGE(podaci!E62:E111) -> 93.2288 | F65: =QUARTILE(podaci!E62:E111,3) -> 94.34 | G65: =MAX(podaci!E62:E111) -> 96.13 | H65: =STDEV(podaci!E62:E111) -> 1.740369
A66: zadnja ploča (%) | B66: =MIN(podaci!F62:F111) -> 76.93 | C66: =QUARTILE(podaci!F62:F111,1) -> 82.935 | D66: =MEDIAN(podaci!F62:F111) -> 85.865 | E66: =AVERAGE(podaci!F62:F111) -> 85.6018 | F66: =QUARTILE(podaci!F62:F111,3) -> 88.21 | G66: =MAX(podaci!F62:F111) -> 92.66 | H66: =STDEV(podaci!F62:F111) -> 3.6030541
A67: pad zadnje ploče (%) | B67: =MIN(podaci!I62:I111) -> -1.34 | C67: =QUARTILE(podaci!I62:I111,1) -> 4.86 | D67: =MEDIAN(podaci!I62:I111) -> 7.47 | E67: =AVERAGE(podaci!I62:I111) -> 7.627 | F67: =QUARTILE(podaci!I62:I111,3) -> 10.2925 | G67: =MAX(podaci!I62:I111) -> 17.8 | H67: =STDEV(podaci!I62:I111) -> 3.9999374
A68: vrijeme (s) | B68: =MIN(podaci!G62:G111) -> 97.21 | C68: =QUARTILE(podaci!G62:G111,1) -> 109.632 | D68: =MEDIAN(podaci!G62:G111) -> 115.294 | E68: =AVERAGE(podaci!G62:G111) -> 119.65062 | F68: =QUARTILE(podaci!G62:G111,3) -> 127.01125 | G68: =MAX(podaci!G62:G111) -> 213.998 | H68: =STDEV(podaci!G62:G111) -> 18.167191
A69: otpad (m²) | B69: =MIN(podaci!H62:H111) -> 0.887374 | C69: =QUARTILE(podaci!H62:H111,1) -> 1.098019 | D69: =MEDIAN(podaci!H62:H111) -> 1.192879 | E69: =AVERAGE(podaci!H62:H111) -> 1.1973988 | F69: =QUARTILE(podaci!H62:H111,3) -> 1.293319 | G69: =MAX(podaci!H62:H111) -> 1.660204 | H69: =STDEV(podaci!H62:H111) -> 0.15339216
A70: Fast Prd preset ↑
A120: metrika | B120: min | C120: q1 | D120: medijan | E120: prosjek | F120: q3 | G120: max | H120: st_dev
A121: ukupna efikasnost (%) | B121: =MIN(podaci!B121:B170) -> 92.15 | C121: =QUARTILE(podaci!B121:B170,1) -> 93.53 | D121: =MEDIAN(podaci!B121:B170) -> 94.085 | E121: =AVERAGE(podaci!B121:B170) -> 94.1794 | F121: =QUARTILE(podaci!B121:B170,3) -> 94.91 | G121: =MAX(podaci!B121:B170) -> 95.42 | H121: =STDEV(podaci!B121:B170) -> 0.7877439
A122: ploča 1 (%) | B122: =MIN(podaci!C121:C170) -> 94.68 | C122: =QUARTILE(podaci!C121:C170,1) -> 96.7525 | D122: =MEDIAN(podaci!C121:C170) -> 97.07 | E122: =AVERAGE(podaci!C121:C170) -> 96.8848 | F122: =QUARTILE(podaci!C121:C170,3) -> 97.42 | G122: =MAX(podaci!C121:C170) -> 97.62 | H122: =STDEV(podaci!C121:C170) -> 0.76071996
A123: ploča 2 (%) | B123: =MIN(podaci!D121:D170) -> 92.66 | C123: =QUARTILE(podaci!D121:D170,1) -> 95.1775 | D123: =MEDIAN(podaci!D121:D170) -> 95.79 | E123: =AVERAGE(podaci!D121:D170) -> 95.6704 | F123: =QUARTILE(podaci!D121:D170,3) -> 96.17 | G123: =MAX(podaci!D121:D170) -> 97.18 | H123: =STDEV(podaci!D121:D170) -> 0.98853625
A124: ploča 3 (%) | B124: =MIN(podaci!E121:E170) -> 88.59 | C124: =QUARTILE(podaci!E121:E170,1) -> 91.7125 | D124: =MEDIAN(podaci!E121:E170) -> 93.025 | E124: =AVERAGE(podaci!E121:E170) -> 92.7844 | F124: =QUARTILE(podaci!E121:E170,3) -> 94.04 | G124: =MAX(podaci!E121:E170) -> 96.05 | H124: =STDEV(podaci!E121:E170) -> 1.6409681
A125: zadnja ploča (%) | B125: =MIN(podaci!F121:F170) -> 78.78 | C125: =QUARTILE(podaci!F121:F170,1) -> 84.245 | D125: =MEDIAN(podaci!F121:F170) -> 86.89 | E125: =AVERAGE(podaci!F121:F170) -> 86.5294 | F125: =QUARTILE(podaci!F121:F170,3) -> 89.285 | G125: =MAX(podaci!F121:F170) -> 93.61 | H125: =STDEV(podaci!F121:F170) -> 3.8703554
A126: pad zadnje ploče (%) | B126: =MIN(podaci!I121:I170) -> -0.26 | C126: =QUARTILE(podaci!I121:I170,1) -> 3.2125 | D126: =MEDIAN(podaci!I121:I170) -> 6.075 | E126: =AVERAGE(podaci!I121:I170) -> 6.255 | F126: =QUARTILE(podaci!I121:I170,3) -> 8.235 | G126: =MAX(podaci!I121:I170) -> 15.57 | H126: =STDEV(podaci!I121:I170) -> 3.8657962
A127: vrijeme (s) | B127: =MIN(podaci!G121:G170) -> 103.472 | C127: =QUARTILE(podaci!G121:G170,1) -> 105.845 | D127: =MEDIAN(podaci!G121:G170) -> 112.1825 | E127: =AVERAGE(podaci!G121:G170) -> 127.22496 | F127: =QUARTILE(podaci!G121:G170,3) -> 123.72975 | G127: =MAX(podaci!G121:G170) -> 226.695 | H127: =STDEV(podaci!G121:G170) -> 37.069238
A128: otpad (m²) | B128: =MIN(podaci!H121:H170) -> 0.887374 | C128: =QUARTILE(podaci!H121:H170,1) -> 1.001764 | D128: =MEDIAN(podaci!H121:H170) -> 1.155214 | E128: =AVERAGE(podaci!H121:H170) -> 1.1620774 | F128: =QUARTILE(podaci!H121:H170,3) -> 1.293319 | G128: =MAX(podaci!H121:H170) -> 1.554184 | H128: =STDEV(podaci!H121:H170) -> 0.16140933
A129: Balanced preset ↑

Sheet usporedba_ploca
A1: ploča | B1: prosjek | C1: min | D1: q1 | E1: medijan | F1: q3 | G1: max
A2: ploča 1 | B2: =AVERAGE(podaci!C2:C51) -> 97.7502 | C2: =MIN(podaci!C2:C51) -> 97.4 | D2: =QUARTILE(podaci!C2:C51,1) -> 97.77 | E2: =MEDIAN(podaci!C2:C51) -> 97.77 | F2: =QUARTILE(podaci!C2:C51,3) -> 97.77 | G2: =MAX(podaci!C2:C51) -> 97.77
A3: ploča 2 | B3: =AVERAGE(podaci!D2:D51) -> 96.3534 | C3: =MIN(podaci!D2:D51) -> 95.56 | D3: =QUARTILE(podaci!D2:D51,1) -> 96.0125 | E3: =MEDIAN(podaci!D2:D51) -> 96.455 | F3: =QUARTILE(podaci!D2:D51,3) -> 96.75 | G3: =MAX(podaci!D2:D51) -> 96.89
A4: ploča 3 | B4: =AVERAGE(podaci!E2:E51) -> 94.5254 | C4: =MIN(podaci!E2:E51) -> 91.99 | D4: =QUARTILE(podaci!E2:E51,1) -> 93.975 | E4: =MEDIAN(podaci!E2:E51) -> 94.525 | F4: =QUARTILE(podaci!E2:E51,3) -> 95.13 | G4: =MAX(podaci!E2:E51) -> 96.89
A5: zadnja ploča | B5: =AVERAGE(podaci!F2:F51) -> 85.332 | C5: =MIN(podaci!F2:F51) -> 73.59 | D5: =QUARTILE(podaci!F2:F51,1) -> 80.57 | E5: =MEDIAN(podaci!F2:F51) -> 86.39 | F5: =QUARTILE(podaci!F2:F51,3) -> 88.915 | G5: =MAX(podaci!F2:F51) -> 94.16
A6: Max Eff preset ↑
A61: ploča | B61: prosjek | C61: min | D61: q1 | E61: medijan | F61: q3 | G61: max
A62: ploča 1 | B62: =AVERAGE(podaci!C62:C111) -> 96.2416 | C62: =MIN(podaci!C62:C111) -> 93.99 | D62: =QUARTILE(podaci!C62:C111,1) -> 95.33 | E62: =MEDIAN(podaci!C62:C111) -> 96.545 | F62: =QUARTILE(podaci!C62:C111,3) -> 97.1375 | G62: =MAX(podaci!C62:C111) -> 97.42
A63: ploča 2 | B63: =AVERAGE(podaci!D62:D111) -> 95.576 | C63: =MIN(podaci!D62:D111) -> 93.53 | D63: =QUARTILE(podaci!D62:D111,1) -> 94.84 | E63: =MEDIAN(podaci!D62:D111) -> 95.8 | F63: =QUARTILE(podaci!D62:D111,3) -> 96.2225 | G63: =MAX(podaci!D62:D111) -> 97.05
A64: ploča 3 | B64: =AVERAGE(podaci!E62:E111) -> 93.2288 | C64: =MIN(podaci!E62:E111) -> 89.71 | D64: =QUARTILE(podaci!E62:E111,1) -> 92.4275 | E64: =MEDIAN(podaci!E62:E111) -> 93.255 | F64: =QUARTILE(podaci!E62:E111,3) -> 94.34 | G64: =MAX(podaci!E62:E111) -> 96.13
A65: zadnja ploča | B65: =AVERAGE(podaci!F62:F111) -> 85.6018 | C65: =MIN(podaci!F62:F111) -> 76.93 | D65: =QUARTILE(podaci!F62:F111,1) -> 82.935 | E65: =MEDIAN(podaci!F62:F111) -> 85.865 | F65: =QUARTILE(podaci!F62:F111,3) -> 88.21 | G65: =MAX(podaci!F62:F111) -> 92.66
A66: Fast Prd preset ↑
A120: ploča | B120: prosjek | C120: min | D120: q1 | E120: medijan | F120: q3 | G120: max
A121: ploča 1 | B121: =AVERAGE(podaci!C121:C170) -> 96.8848 | C121: =MIN(podaci!C121:C170) -> 94.68 | D121: =QUARTILE(podaci!C121:C170,1) -> 96.7525 | E121: =MEDIAN(podaci!C121:C170) -> 97.07 | F121: =QUARTILE(podaci!C121:C170,3) -> 97.42 | G121: =MAX(podaci!C121:C170) -> 97.62
A122: ploča 2 | B122: =AVERAGE(podaci!D121:D170) -> 95.6704 | C122: =MIN(podaci!D121:D170) -> 92.66 | D122: =QUARTILE(podaci!D121:D170,1) -> 95.1775 | E122: =MEDIAN(podaci!D121:D170) -> 95.79 | F122: =QUARTILE(podaci!D121:D170,3) -> 96.17 | G122: =MAX(podaci!D121:D170) -> 97.18
A123: ploča 3 | B123: =AVERAGE(podaci!E121:E170) -> 92.7844 | C123: =MIN(podaci!E121:E170) -> 88.59 | D123: =QUARTILE(podaci!E121:E170,1) -> 91.7125 | E123: =MEDIAN(podaci!E121:E170) -> 93.025 | F123: =QUARTILE(podaci!E121:E170,3) -> 94.04 | G123: =MAX(podaci!E121:E170) -> 96.05
A124: zadnja ploča | B124: =AVERAGE(podaci!F121:F170) -> 86.5294 | C124: =MIN(podaci!F121:F170) -> 78.78 | D124: =QUARTILE(podaci!F121:F170,1) -> 84.245 | E124: =MEDIAN(podaci!F121:F170) -> 86.89 | F124: =QUARTILE(podaci!F121:F170,3) -> 89.285 | G124: =MAX(podaci!F121:F170) -> 93.61
A125: Balanced preset ↑

Sheet vs_referenca
A1: metrika | B1: GuillotineStrip | C1: referenca | D1: razlika | E1: razlika_%
A2: Minimum | B2: =MIN(podaci!B2:B51) -> 93.68 | C2: 91.41 | D2: =B2-C2 -> 2.27 | E2: =(B2-C2)/C2*100 -> 2.4833169
A3: Q1 (25%) | B3: =QUARTILE(podaci!B2:B51,1) -> 94.47 | C3: 91.41 | D3: =B3-C3 -> 3.06 | E3: =(B3-C3)/C3*100 -> 3.347555
A4: Medijan | B4: =MEDIAN(podaci!B2:B51) -> 95.185 | C4: 91.41 | D4: =B4-C4 -> 3.775 | E4: =(B4-C4)/C4*100 -> 4.1297451
A5: Prosjek | B5: =AVERAGE(podaci!B2:B51) -> 95.1094 | C5: 91.41 | D5: =B5-C5 -> 3.6994 | E5: =(B5-C5)/C5*100 -> 4.0470408
A6: Q3 (75%) | B6: =QUARTILE(podaci!B2:B51,3) -> 95.595 | C6: 91.41 | D6: =B6-C6 -> 4.185 | E6: =(B6-C6)/C6*100 -> 4.5782737
A7: Maksimum | B7: =MAX(podaci!B2:B51) -> 96.42 | C7: 91.41 | D7: =B7-C7 -> 5.01 | E7: =(B7-C7)/C7*100 -> 5.4808008
A8: Max Eff preset ↑
A61: metrika | B61: GuillotineStrip | C61: referenca | D61: razlika | E61: razlika_%
A62: Minimum | B62: =MIN(podaci!B62:B111) -> 92.3 | C62: 91.41 | D62: =B62-C62 -> 0.89 | E62: =(B62-C62)/C62*100 -> 0.97363527
A63: Q1 (25%) | B63: =QUARTILE(podaci!B62:B111,1) -> 93.52 | C63: 91.41 | D63: =B63-C63 -> 2.11 | E63: =(B63-C63)/C63*100 -> 2.3082814
A64: Medijan | B64: =MEDIAN(podaci!B62:B111) -> 93.945 | C64: 91.41 | D64: =B64-C64 -> 2.535 | E64: =(B64-C64)/C64*100 -> 2.7732196
A65: Prosjek | B65: =AVERAGE(podaci!B62:B111) -> 93.9772 | C65: 91.41 | D65: =B65-C65 -> 2.5672 | E65: =(B65-C65)/C65*100 -> 2.8084455
A66: Q3 (75%) | B66: =QUARTILE(podaci!B62:B111,3) -> 94.4925 | C66: 91.41 | D66: =B66-C66 -> 3.0825 | E66: =(B66-C66)/C66*100 -> 3.3721693
A67: Maksimum | B67: =MAX(podaci!B62:B111) -> 95.64 | C67: 91.41 | D67: =B67-C67 -> 4.23 | E67: =(B67-C67)/C67*100 -> 4.6275025
A68: Fast Prd preset ↑
A120: metrika | B120: GuillotineStrip | C120: referenca | D120: razlika | E120: razlika_%
A121: Minimum | B121: =MIN(podaci!B121:B170) -> 92.15 | C121: 91.41 | D121: =B121-C121 -> 0.74 | E121: =(B121-C121)/C121*100 -> 0.80953944
A122: Q1 (25%) | B122: =QUARTILE(podaci!B121:B170,1) -> 93.53 | C122: 91.41 | D122: =B122-C122 -> 2.12 | E122: =(B122-C122)/C122*100 -> 2.3192211
A123: Medijan | B123: =MEDIAN(podaci!B121:B170) -> 94.085 | C123: 91.41 | D123: =B123-C123 -> 2.675 | E123: =(B123-C123)/C123*100 -> 2.9263757
A124: Prosjek | B124: =AVERAGE(podaci!B121:B170) -> 94.1794 | C124: 91.41 | D124: =B124-C124 -> 2.7694 | E124: =(B124-C124)/C124*100 -> 3.0296466
A125: Q3 (75%) | B125: =QUARTILE(podaci!B121:B170,3) -> 94.91 | C125: 91.41 | D125: =B125-C125 -> 3.5 | E125: =(B125-C125)/C125*100 -> 3.8289027
A126: Maksimum | B126: =MAX(podaci!B121:B170) -> 95.42 | C126: 91.41 | D126: =B126-C126 -> 4.01 | E126: =(B126-C126)/C126*100 -> 4.3868286
A127: Balanced preset ↑

Sheet najbolji_vs_najgori
A1: helperi izračuni
A3: najbolji run: | B3: =INDEX(podaci!A2:A51,MATCH(MAX(podaci!B2:B51),podaci!B2:B51,0)) -> 23
A4: najgori run: | B4: =INDEX(podaci!A2:A51,MATCH(MIN(podaci!B2:B51),podaci!B2:B51,0)) -> 34
A5: najbolji row: | B5: =MATCH(B3,podaci!A2:A51,0)+1 -> 24
A6: najgori row: | B6: =MATCH(B4,podaci!A2:A51,0)+1 -> 35
A7: Max Eff preset ↑
A9: metrika | B9: najbolji | C9: najgori | D9: razlika
A10: run id | B10: =INDIRECT("podaci!A"&B5) -> 23 | C10: =INDIRECT("podaci!A"&B6) -> 34
A11: Ukupna efikasnost (%) | B11: =INDIRECT("podaci!B"&B5) -> 96.42 | C11: =INDIRECT("podaci!B"&B6) -> 93.68 | D11: =B11-C11 -> 2.74
A12: Ploča 1 (%) | B12: =INDIRECT("podaci!C"&B5) -> 97.62 | C12: =INDIRECT("podaci!C"&B6) -> 97.77 | D12: =B12-C12 -> -0.15
A13: Ploča 2 (%) | B13: =INDIRECT("podaci!D"&B5) -> 96.75 | C13: =INDIRECT("podaci!D"&B6) -> 96.56 | D13: =B13-C13 -> 0.19
A14: Ploča 3 (%) | B14: =INDIRECT("podaci!E"&B5) -> 96.89 | C14: =INDIRECT("podaci!E"&B6) -> 94.27 | D14: =B14-C14 -> 2.62
A15: Ploča 4 (%) | B15: =INDIRECT("podaci!F"&B5) -> 89.3 | C15: =INDIRECT("podaci!F"&B6) -> 73.59 | D15: =B15-C15 -> 15.71
A16: pad na zadnjoj (%) | B16: =INDIRECT("podaci!I"&B5) -> 7.59 | C16: =INDIRECT("podaci!I"&B6) -> 20.68 | D16: =B16-C16 -> -13.09
A17: vrijeme (s) | B17: =INDIRECT("podaci!G"&B5) -> 88.328 | C17: =INDIRECT("podaci!G"&B6) -> 91.189 | D17: =B17-C17 -> -2.861
A18: otpad (m²) | B18: =INDIRECT("podaci!H"&B5) -> 0.697654 | C18: =INDIRECT("podaci!H"&B6) -> 1.389574 | D18: =B18-C18 -> -0.69192
A61: helperi izračuni
A63: najbolji run: | B63: =INDEX(podaci!A62:A111,MATCH(MAX(podaci!B62:B111),podaci!B62:B111,0)) -> 48
A64: najgori run: | B64: =INDEX(podaci!A62:A111,MATCH(MIN(podaci!B62:B111),podaci!B62:B111,0)) -> 49
A65: najbolji row: | B65: =MATCH(B63,podaci!A62:A111,0)+61 -> 109
A66: najgori row: | B66: =MATCH(B64,podaci!A62:A111,0)+61 -> 110
A67: Fast Prd preset ↑
A69: metrika | B69: najbolji | C69: najgori | D69: razlika
A70: run id | B70: =INDIRECT("podaci!A"&B65) -> 48 | C70: =INDIRECT("podaci!A"&B66) -> 49
A71: Ukupna efikasnost (%) | B71: =INDIRECT("podaci!B"&B65) -> 95.64 | C71: =INDIRECT("podaci!B"&B66) -> 92.3 | D71: =B71-C71 -> 3.34
A72: Sheet 1 (%) | B72: =INDIRECT("podaci!C"&B65) -> 96.85 | C72: =INDIRECT("podaci!C"&B66) -> 93.99 | D72: =B72-C72 -> 2.86
A73: Sheet 2 (%) | B73: =INDIRECT("podaci!D"&B65) -> 96.72 | C73: =INDIRECT("podaci!D"&B66) -> 93.92 | D73: =B73-C73 -> 2.8
A74: Sheet 3 (%) | B74: =INDIRECT("podaci!E"&B65) -> 94.26 | C74: =INDIRECT("podaci!E"&B66) -> 93.33 | D74: =B74-C74 -> 0.93
A75: Sheet 4 (%) | B75: =INDIRECT("podaci!F"&B65) -> 92.66 | C75: =INDIRECT("podaci!F"&B66) -> 82.19 | D75: =B75-C75 -> 10.47
A76: pad na zadnjoj (%) | B76: =INDIRECT("podaci!I"&B65) -> 1.6 | C76: =INDIRECT("podaci!I"&B66) -> 11.14 | D76: =B76-C76 -> -9.54
A77: vrijeme (s) | B77: =INDIRECT("podaci!G"&B65) -> 112.858 | C77: =INDIRECT("podaci!G"&B66) -> 127.259 | D77: =B77-C77 -> -14.401
A78: otpad (m²) | B78: =INDIRECT("podaci!H"&B65) -> 0.934804 | C78: =INDIRECT("podaci!H"&B66) -> 1.543024 | D78: =B78-C78 -> -0.60822
A120: helperi izračuni
A122: najbolji run: | B122: =INDEX(podaci!A121:A170,MATCH(MAX(podaci!B121:B170),podaci!B121:B170,0)) -> 6
A123: najgori run: | B123: =INDEX(podaci!A121:A170,MATCH(MIN(podaci!B121:B170),podaci!B121:B170,0)) -> 25
A124: najbolji row: | B124: =MATCH(B122,podaci!A121:A170,0)+120 -> 126
A125: najgori row: | B125: =MATCH(B123,podaci!A121:A170,0)+120 -> 145
A126: Balanced preset ↑
A128: metrika | B128: najbolji | C128: najgori | D128: razlika
A129: run id | B129: =INDIRECT("podaci!A"&B124) -> 6 | C129: =INDIRECT("podaci!A"&B125) -> 25
...

Sheet rezultati
A1: rezultati
A2: Ref value | B2: 91.41
A3: metrika | B3: vrijednost | C3: napomena
A4: prosjek efikasnost (%) | B4: =statistika!E2 -> 95.1094 | C4: statistika, red 2
A5: poboljšanje vs ref (pp) | B5: =statistika!E2-B2 -> 3.6994 | C5: postotni poeni
A6: poboljšanje vs ref (%) | B6: =(statistika!E2-B2)/B2*100 -> 4.0470408 | C6: relativno poboljšanje
A7: st. devijacija (%) | B7: =statistika!H2 -> 0.77044755 | C7: konzistentnost
A8: minimum (%) | B8: =statistika!B2 -> 93.68 | C8: najgori slučaj
A9: maksimum (%) | B9: =statistika!G2 -> 96.42 | C9: najbolji slučaj
A10: raspon | B10: =statistika!G2-statistika!B2 -> 2.74 | C10: max - min
A12: zadnja ploča
A13: efikasnost zadnje (%) | B13: =statistika!E6 -> 85.332
A14: prosječan pad (%) | B14: =statistika!E7 -> 9.1934
A15: najbolji pad (%) | B15: =statistika!B7 -> 0.98 | C15: minimalni pad = best
A16: najgori pad (%) | B16: =statistika!G7 -> 21.26 | C16: maksimalni pad = worst
A18: vrijeme i otpad
A19: prosječno vrijeme (s) | B19: =statistika!E8 -> 108.7204 | C19: sekunde
A20: prosječan otpad (m²) | B20: =statistika!E9 -> 1.0280458 | C20: kvadratni metri
A21: Max Eff preset ↑
A61: rezultati
A62: Ref value | B62: 91.41
A63: metrika | B63: vrijednost | C63: napomena
A64: prosjek efikasnost (%) | B64: =statistika!E62 -> 93.9772 | C64: statistika, red 2
A65: poboljšanje vs ref (pp) | B65: =statistika!E62-B62 -> 2.5672 | C65: postotni poeni
A66: poboljšanje vs ref (%) | B66: =(statistika!E62-B62)/B62*100 -> 2.8084455 | C66: relativno poboljšanje
A67: st. devijacija (%) | B67: =statistika!H62 -> 0.70824313 | C67: konzistentnost
A68: minimum (%) | B68: =statistika!B62 -> 92.3 | C68: najgori slučaj
A69: maksimum (%) | B69: =statistika!G62 -> 95.64 | C69: najbolji slučaj
A70: raspon | B70: =statistika!G62-statistika!B62 -> 3.34 | C70: max - min
A72: zadnja ploča
A73: efikasnost zadnje (%) | B73: =statistika!E66 -> 85.6018
A74: prosječan pad (%) | B74: =statistika!E67 -> 7.627
A75: najbolji pad (%) | B75: =statistika!B67 -> -1.34 | C75: minimalni pad = best
A76: najgori pad (%) | B76: =statistika!G67 -> 17.8 | C76: maksimalni pad = worst
A78: vrijeme i otpad
A79: prosječno vrijeme (s) | B79: =statistika!E68 -> 119.65062 | C79: sekunde
A80: prosječan otpad (m²) | B80: =statistika!E69 -> 1.1973988 | C80: kvadratni metri
A81: Fast Prd preset ↑
A120: rezultati
A121: Ref value | B121: 91.41
...

Sheet grafovi_final
A1: MAX | S1: FAST PROD | AJ1: BALANCED
